Workbook

Sheet BASE GERAL
A1: NÚMERO | B1: CURSO | C1: TEMPO | D1: JANEIRO | E1: FEVEREIRO | F1: MARÇO | G1: ABRIL | H1: MAIO | I1: JUNHO | J1: JULHO | K1: AGOSTO | L1: SETEMBRO | M1: OUTUBRO | N1: NOVEMBRO | O1: DEZEMBRO
A2: 1 | B2: ='[2]1'!$C$1 -> Especialização em Direito do Consumidor | C2: 12 | D2: ='DEZ24'!L3 -> HOSPITAIS E PLANOS DE SAÚDE FRENTE AO CDC | E2: =DEZEMBRO26!K3 -> PUBLICIDADE E PROPAGANDA NO CDC | F2: =JANEIRO26!K2 -> DEFESA DO CONSUMIDOR EM JUÍZO: DIREITO COLETIVO E DIREITO INDIVIDUAL | G2: =#REF! -> #REF! | H2: =#REF! -> #REF! | I2: =#REF! -> #REF! | J2: =#REF! -> #REF! | K2: =#REF! -> #REF! | L2: =#REF! -> #REF! | M2: =#REF! -> #REF! | N2: =#REF! -> #REF! | O2: =#REF! -> #REF!
A3: 2 | B3: ='[2]2'!$C$1 -> Especialização em Direito nas Relações de Consumo | C3: 6 | D3: ='DEZ24'!L4 -> Publicidade e Propaganda no CDC | E3: =DEZEMBRO26!K4 -> Direito Constitucional Econômico e Regulatório | F3: =JANEIRO26!K3 -> Autuação, Processos e Sanções Administrativos | G3: =#REF! -> #REF! | H3: =#REF! -> #REF! | I3: =#REF! -> #REF! | J3: =#REF! -> #REF! | K3: =#REF! -> #REF! | L3: =#REF! -> #REF! | M3: =#REF! -> #REF! | N3: =#REF! -> #REF! | O3: =#REF! -> #REF!
D4: ='DEZ24'!L5 -> A Proteção Contratual do Consumidor | E4: =DEZEMBRO26!K5 -> As Empresas de Telefonia à Luz do CDC | F4: =JANEIRO26!K4 -> Responsabilidade Civil e o Código de Defesa do Consumidor | G4: =#REF! -> #REF! | H4: =#REF! -> #REF! | I4: =#REF! -> #REF! | J4: =#REF! -> #REF! | K4: =#REF! -> #REF! | L4: =#REF! -> #REF! | M4: =#REF! -> #REF! | N4: =#REF! -> #REF! | O4: =#REF! -> #REF!
A5: 3 | B5: ='[2]3'!$C$1 -> Especialização em Direito Civil e Processo Civil | C5: 12 | D5: ='DEZ24'!L6 -> Processo Constitucional | E5: =DEZEMBRO26!K6 -> Direito da Sucessões | F5: =JANEIRO26!K5 -> Mediação e Arbitragem | G5: =#REF! -> #REF! | H5: =#REF! -> #REF! | I5: =#REF! -> #REF! | J5: =#REF! -> #REF! | K5: =#REF! -> #REF! | L5: =#REF! -> #REF! | M5: =#REF! -> #REF! | N5: =#REF! -> #REF! | O5: =#REF! -> #REF!
A6: 4 | B6: ='[2]4'!$C$1 -> Especialização em Direito Civil | C6: 6 | D6: ='DEZ24'!L7 -> Direito da Sucessões | E6: =DEZEMBRO26!K7 -> Processo Civil: Execução | F6: =JANEIRO26!K6 -> Aspectos Processuais dos Juizados Especiais, Estaduais e Federais | G6: =#REF! -> #REF! | H6: =#REF! -> #REF! | I6: =#REF! -> #REF! | J6: =#REF! -> #REF! | K6: =#REF! -> #REF! | L6: =#REF! -> #REF! | M6: =#REF! -> #REF! | N6: =#REF! -> #REF! | O6: =#REF! -> #REF!
D7: ='DEZ24'!L8 -> Direito Civil: Parte Geral e Obrigações | E7: =DEZEMBRO26!K8 -> Processo Civil: Teoria Geral do Processo e Processo de Conhecimento | F7: =JANEIRO26!K7 -> Processo Civil: Cautelar e Recursos | G7: =#REF! -> #REF! | H7: =#REF! -> #REF! | I7: =#REF! -> #REF! | J7: =#REF! -> #REF! | K7: =#REF! -> #REF! | L7: =#REF! -> #REF! | M7: =#REF! -> #REF! | N7: =#REF! -> #REF! | O7: =#REF! -> #REF!
A8: 5 | B8: ='[2]5'!$C$1 -> Especialização em Direito Material e Processual do Trabalho | C8: 12 | D8: ='DEZ24'!L9 -> Ministério Público do Trabalho | E8: =DEZEMBRO26!K9 -> Direito Individual do Trabalho - Contrato de Trabalho | F8: =JANEIRO26!K8 -> Direito Constitucional do Trabalho | G8: =#REF! -> #REF! | H8: =#REF! -> #REF! | I8: =#REF! -> #REF! | J8: =#REF! -> #REF! | K8: =#REF! -> #REF! | L8: =#REF! -> #REF! | M8: =#REF! -> #REF! | N8: =#REF! -> #REF! | O8: =#REF! -> #REF!
A9: 6 | B9: ='[2]6'!$C$1 -> Especialização em Direito do Trabalho | C9: 6 | D9: ='DEZ24'!L10 -> Direito Individual do Trabalho - Contrato de Trabalho | E9: =DEZEMBRO26!K10 -> Direito Previdenciário Aplicado à Relações de Trabalho | F9: =JANEIRO26!K9 -> Meio Ambiente do Trabalho | G9: =#REF! -> #REF! | H9: =#REF! -> #REF! | I9: =#REF! -> #REF! | J9: =#REF! -> #REF! | K9: =#REF! -> #REF! | L9: =#REF! -> #REF! | M9: =#REF! -> #REF! | N9: =#REF! -> #REF! | O9: =#REF! -> #REF!
D10: ='DEZ24'!L11 -> A Interpretação da Jurisprudência do TST em Matéria de Direito e Processo do Trabalho | E10: =DEZEMBRO26!K11 -> Processo do Trabalho - Justiça do Trabalho | F10: =JANEIRO26!K10 -> Processo do Trabalho - Recursos | G10: =#REF! -> #REF! | H10: =#REF! -> #REF! | I10: =#REF! -> #REF! | J10: =#REF! -> #REF! | K10: =#REF! -> #REF! | L10: =#REF! -> #REF! | M10: =#REF! -> #REF! | N10: =#REF! -> #REF! | O10: =#REF! -> #REF!
A11: 7 | B11: ='[2]7'!$C$1 -> Especialização em Direito Ambiental | C11: 12 | D11: ='DEZ24'!L12 -> Tutela Civil do Meio Ambiente | E11: =DEZEMBRO26!K12 -> Tutela e responsabilidade Administrativa do Meio Ambiente | F11: =JANEIRO26!K11 -> Tutela e Responsabilidade Penal | G11: =#REF! -> #REF! | H11: =#REF! -> #REF! | I11: =#REF! -> #REF! | J11: =#REF! -> #REF! | K11: =#REF! -> #REF! | L11: =#REF! -> #REF! | M11: =#REF! -> #REF! | N11: =#REF! -> #REF! | O11: =#REF! -> #REF!
A12: 8 | B12: ='[2]8'!$C$1 -> Especialização em Direito e Meio Ambiente | C12: 6 | D12: ='DEZ24'!L13 -> Tutela e responsabilidade Administrativa do Meio Ambiente | E12: =DEZEMBRO26!K13 -> Cadastro Técnico e Relatórios Ambientais | F12: =JANEIRO26!K12 -> Estudo de impacto ambiental (EIA) e Relatório de impacto ambiental (RIMA) | G12: =#REF! -> #REF! | H12: =#REF! -> #REF! | I12: =#REF! -> #REF! | J12: =#REF! -> #REF! | K12: =#REF! -> #REF! | L12: =#REF! -> #REF! | M12: =#REF! -> #REF! | N12: =#REF! -> #REF! | O12: =#REF! -> #REF!
D13: ='DEZ24'!L14 -> Licenciamento Ambiental | E13: =DEZEMBRO26!K14 -> Meio Ambiente do Trabalho | F13: =JANEIRO26!K13 -> O Direito Constitucional e a questão ambiental | G13: =#REF! -> #REF! | H13: =#REF! -> #REF! | I13: =#REF! -> #REF! | J13: =#REF! -> #REF! | K13: =#REF! -> #REF! | L13: =#REF! -> #REF! | M13: =#REF! -> #REF! | N13: =#REF! -> #REF! | O13: =#REF! -> #REF!
A14: 9 | B14: ='[2]9'!$C$1 -> MBA em Gestão da Qualidade e Gestão Ambiental | C14: 12 | D14: ='DEZ24'!L15 -> NBR - ISO 14001 e Auditorias Ambientais | E14: =DEZEMBRO26!K15 -> Metodologia 6 Sigmas | F14: =JANEIRO26!K14 -> Ações Corretivas e Preventivas para Qualidade e Ambientais | G14: =#REF! -> #REF! | H14: =#REF! -> #REF! | I14: =#REF! -> #REF! | J14: =#REF! -> #REF! | K14: =#REF! -> #REF! | L14: =#REF! -> #REF! | M14: =#REF! -> #REF! | N14: =#REF! -> #REF! | O14: =#REF! -> #REF!
A15: 10 | B15: ='[2]10'!$C$1 -> MBA em Meio Ambiente e Gestão da Qualidade | C15: 6 | D15: ='DEZ24'!L16 -> Metodologia 6 Sigmas | E15: =DEZEMBRO26!K16 -> Conceitos e Ferramentas da Qualidade | F15: =JANEIRO26!K15 -> Visão Estratégica e Indicadores de Desempenho | G15: =#REF! -> #REF! | H15: =#REF! -> #REF! | I15: =#REF! -> #REF! | J15: =#REF! -> #REF! | K15: =#REF! -> #REF! | L15: =#REF! -> #REF! | M15: =#REF! -> #REF! | N15: =#REF! -> #REF! | O15: =#REF! -> #REF!
D16: ='DEZ24'!L17 -> Padronização e Controle de Documentos e Registros | E16: =DEZEMBRO26!K17 -> Recursos Humanos Voltados para Gestão da Qualidade e Ambiental | F16: =JANEIRO26!K16 -> Gerenciamento de Processos | G16: =#REF! -> #REF! | H16: =#REF! -> #REF! | I16: =#REF! -> #REF! | J16: =#REF! -> #REF! | K16: =#REF! -> #REF! | L16: =#REF! -> #REF! | M16: =#REF! -> #REF! | N16: =#REF! -> #REF! | O16: =#REF! -> #REF!
A17: 11 | B17: ='[2]11'!$C$1 -> MBA em Gestão Empresarial | C17: 12 | D17: ='DEZ24'!L18 -> GESTÃO DE COMPRAS E LOGÍSTICA | E17: =DEZEMBRO26!K18 -> PLANEJAMENTO ESTRATÉGICO | F17: =JANEIRO26!K17 -> GESTÃO DE RELACIONAMENTO COM O CLIENTE | G17: =#REF! -> #REF! | H17: =#REF! -> #REF! | I17: =#REF! -> #REF! | J17: =#REF! -> #REF! | K17: =#REF! -> #REF! | L17: =#REF! -> #REF! | M17: =#REF! -> #REF! | N17: =#REF! -> #REF! | O17: =#REF! -> #REF!
A18: 12 | B18: ='[2]12'!$C$1 -> MBA em Gestão de Empresas | C18: 6 | D18: ='DEZ24'!L19 -> PLANEJAMENTO ESTRATÉGICO | E18: =DEZEMBRO26!K19 -> GESTÃO DE DESEMPENHO E COMPETÊNCIA | F18: =JANEIRO26!K18 -> NEGOCIAÇÃO PARA LIDERES | G18: =#REF! -> #REF! | H18: =#REF! -> #REF! | I18: =#REF! -> #REF! | J18: =#REF! -> #REF! | K18: =#REF! -> #REF! | L18: =#REF! -> #REF! | M18: =#REF! -> #REF! | N18: =#REF! -> #REF! | O18: =#REF! -> #REF!
D19: ='DEZ24'!L20 -> ASSESMENT, COACHING E MENTORING | E19: =DEZEMBRO26!K20 -> FUNDAMENTOS DA ADMINISTRAÇÃO | F19: =JANEIRO26!K19 -> GESTÃO CONTÁBIL | G19: =#REF! -> #REF! | H19: =#REF! -> #REF! | I19: =#REF! -> #REF! | J19: =#REF! -> #REF! | K19: =#REF! -> #REF! | L19: =#REF! -> #REF! | M19: =#REF! -> #REF! | N19: =#REF! -> #REF! | O19: =#REF! -> #REF!
A20: 13 | B20: ='[2]13'!$C$1 -> MBA em Gestão Pública | C20: 12 | D20: ='DEZ24'!L21 -> Gestão Ambiental, Ética e Cidadania na Gestão Pública | E20: =DEZEMBRO26!K21 -> Gestão Estratégica da Tecnologia da Informação | F20: =JANEIRO26!K20 -> Planejamento Estratégico | G20: =#REF! -> #REF! | H20: =#REF! -> #REF! | I20: =#REF! -> #REF! | J20: =#REF! -> #REF! | K20: =#REF! -> #REF! | L20: =#REF! -> #REF! | M20: =#REF! -> #REF! | N20: =#REF! -> #REF! | O20: =#REF! -> #REF!
A21: 14 | B21: ='[2]14'!$C$1 -> MBA em Administração Pública | C21: 6 | D21: ='DEZ24'!L22 -> Gestão Estratégica da Tecnologia da Informação | E21: =DEZEMBRO26!K22 -> Gestão Participativa | F21: =JANEIRO26!K21 -> Lógica | G21: =#REF! -> #REF! | H21: =#REF! -> #REF! | I21: =#REF! -> #REF! | J21: =#REF! -> #REF! | K21: =#REF! -> #REF! | L21: =#REF! -> #REF! | M21: =#REF! -> #REF! | N21: =#REF! -> #REF! | O21: =#REF! -> #REF!
D22: ='DEZ24'!L23 -> Direito Constitucional e Administrativo | E22: =DEZEMBRO26!K23 -> Fundamentos da Administração | F22: =JANEIRO26!K22 -> Estado e Administração Pública | G22: =#REF! -> #REF! | H22: =#REF! -> #REF! | I22: =#REF! -> #REF! | J22: =#REF! -> #REF! | K22: =#REF! -> #REF! | L22: =#REF! -> #REF! | M22: =#REF! -> #REF! | N22: =#REF! -> #REF! | O22: =#REF! -> #REF!
A23: 15 | B23: ='[2]15'!$C$1 -> MBA em Gestão de Projetos | C23: 12 | D23: ='DEZ24'!L24 -> GESTÃO DE CONTRATAÇÃO DE PROJETOS | E23: =DEZEMBRO26!K24 -> GESTÃO ESTRATÉGICA DE PESSOAS | F23: =JANEIRO26!K23 -> GESTÃO DE ESCOPO DE PROJETOS | G23: =#REF! -> #REF! | H23: =#REF! -> #REF! | I23: =#REF! -> #REF! | J23: =#REF! -> #REF! | K23: =#REF! -> #REF! | L23: =#REF! -> #REF! | M23: =#REF! -> #REF! | N23: =#REF! -> #REF! | O23: =#REF! -> #REF!
A24: 16 | B24: ='[2]16'!$C$1 -> MBA em Gerenciamento de Projetos | C24: 6 | D24: ='DEZ24'!L25 -> GESTÃO DE CONTRATAÇÃO DE PROJETOS | E24: =DEZEMBRO26!K25 -> GESTÃO ESTRATÉGICA DE PESSOAS | F24: =JANEIRO26!K24 -> GESTÃO DE ESCOPO DE PROJETOS | G24: =#REF! -> #REF! | H24: =#REF! -> #REF! | I24: =#REF! -> #REF! | J24: =#REF! -> #REF! | K24: =#REF! -> #REF! | L24: =#REF! -> #REF! | M24: =#REF! -> #REF! | N24: =#REF! -> #REF! | O24: =#REF! -> #REF!
D25: ='DEZ24'!L26 -> ASSESMENT, COACHING E MENTORING | E25: =DEZEMBRO26!K26 -> ANÁLISE DE VIABILIDADE E GERÊNCIA FINANCEIRA DE PROJETOS | F25: =JANEIRO26!K25 -> PRINCÍPIOS DE GERÊNCIA DE PROJETOS | G25: =#REF! -> #REF! | H25: =#REF! -> #REF! | I25: =#REF! -> #REF! | J25: =#REF! -> #REF! | K25: =#REF! -> #REF! | L25: =#REF! -> #REF! | M25: =#REF! -> #REF! | N25: =#REF! -> #REF! | O25: =#REF! -> #REF!
A26: 17 | B26: ='[2]17'!$C$1 -> MBA em Logística Empresarial | C26: 12 | D26: ='DEZ24'!L27 -> Gestão de Compras e Logística | E26: =DEZEMBRO26!K27 -> Liderança e Desenvolvimento de Equipes | F26: =JANEIRO26!K26 -> Logística e Distribuição | G26: =#REF! -> #REF! | H26: =#REF! -> #REF! | I26: =#REF! -> #REF! | J26: =#REF! -> #REF! | K26: =#REF! -> #REF! | L26: =#REF! -> #REF! | M26: =#REF! -> #REF! | N26: =#REF! -> #REF! | O26: =#REF! -> #REF!
A27: 18 | B27: ='[2]18'!$C$1 -> MBA em Logística nas Organizações | C27: 6 | D27: ='DEZ24'!L28 -> Liderança e Desenvolvimento de Equipes | E27: =DEZEMBRO26!K28 -> Gestão de Transportes | F27: =JANEIRO26!K27 -> Logística e Distribuição | G27: =#REF! -> #REF! | H27: =#REF! -> #REF! | I27: =#REF! -> #REF! | J27: =#REF! -> #REF! | K27: =#REF! -> #REF! | L27: =#REF! -> #REF! | M27: =#REF! -> #REF! | N27: =#REF! -> #REF! | O27: =#REF! -> #REF!
D28: ='DEZ24'!L29 -> Gestão da Tecnologia e Informação em Logística - GTI | E28: =DEZEMBRO26!K29 -> Gestão de Compras e Logística | F28: =JANEIRO26!K28 -> Gestão de Custos, Riscos e Perdas | G28: =#REF! -> #REF! | H28: =#REF! -> #REF! | I28: =#REF! -> #REF! | J28: =#REF! -> #REF! | K28: =#REF! -> #REF! | L28: =#REF! -> #REF! | M28: =#REF! -> #REF! | N28: =#REF! -> #REF! | O28: =#REF! -> #REF!
A29: 19 | B29: ='[2]19'!$C$1 -> MBA em Gestão de Pessoas e Relações Trabalhistas | C29: 12 | D29: ='DEZ24'!L30 -> Gestão da Captação e Retenção de Talentos | E29: =DEZEMBRO26!K30 -> Seleção, Treinamento e Dinâmica de Grupo | F29: =JANEIRO26!K29 -> Direito Constitucional do Trabalho | G29: =#REF! -> #REF! | H29: =#REF! -> #REF! | I29: =#REF! -> #REF! | J29: =#REF! -> #REF! | K29: =#REF! -> #REF! | L29: =#REF! -> #REF! | M29: =#REF! -> #REF! | N29: =#REF! -> #REF! | O29: =#REF! -> #REF!
A30: 20 | B30: ='[2]20'!$C$1 -> MBA em Gestão de Relações Trabalhistas | C30: 6 | D30: ='DEZ24'!L31 -> Seleção, Treinamento e Dinâmica de Grupo | E30: =DEZEMBRO26!K31 -> Gestão de Desempenho e Competência | F30: =JANEIRO26!K30 -> Direito Constitucional do Trabalho | G30: =#REF! -> #REF! | H30: =#REF! -> #REF! | I30: =#REF! -> #REF! | J30: =#REF! -> #REF! | K30: =#REF! -> #REF! | L30: =#REF! -> #REF! | M30: =#REF! -> #REF! | N30: =#REF! -> #REF! | O30: =#REF! -> #REF!
D31: ='DEZ24'!L32 -> Assesment, Coaching e Mentoring | E31: =DEZEMBRO26!K32 -> Gestão da Captação e Retenção de Talentos | F31: =JANEIRO26!K31 -> Direito Individual do Trabalho - Contrato de Trabalho | G31: =#REF! -> #REF! | H31: =#REF! -> #REF! | I31: =#REF! -> #REF! | J31: =#REF! -> #REF! | K31: =#REF! -> #REF! | L31: =#REF! -> #REF! | M31: =#REF! -> #REF! | N31: =#REF! -> #REF! | O31: =#REF! -> #REF!
A32: 21 | B32: ='[2]21'!$C$1 -> MBA em Gestão Hospitalar | C32: 12 | D32: ='DEZ24'!L33 -> Gestão e Marketing Hopitalar | E32: =DEZEMBRO26!K33 -> Gestão Contábil | F32: =JANEIRO26!K32 -> Auditoria Hospitalar | G32: =#REF! -> #REF! | H32: =#REF! -> #REF! | I32: =#REF! -> #REF! | J32: =#REF! -> #REF! | K32: =#REF! -> #REF! | L32: =#REF! -> #REF! | M32: =#REF! -> #REF! | N32: =#REF! -> #REF! | O32: =#REF! -> #REF!
A33: 22 | B33: ='[2]22'!$C$1 -> MBA em Gestão em Unidades Hospitalares | C33: 6 | D33: ='DEZ24'!L34 -> Gestão e Marketing Hospitalar | E33: =DEZEMBRO26!K34 -> Gestão Contábil | F33: =JANEIRO26!K33 -> Auditoria Hospitalar | G33: =#REF! -> #REF! | H33: =#REF! -> #REF! | I33: =#REF! -> #REF! | J33: =#REF! -> #REF! | K33: =#REF! -> #REF! | L33: =#REF! -> #REF! | M33: =#REF! -> #REF! | N33: =#REF! -> #REF! | O33: =#REF! -> #REF!
D34: ='DEZ24'!L35 -> Sistema de Informação para Saúde | E34: =DEZEMBRO26!K35 -> Hotelaria Hospitalar | F34: =JANEIRO26!K34 -> Gestão Estratégica de Pessoas | G34: =#REF! -> #REF! | H34: =#REF! -> #REF! | I34: =#REF! -> #REF! | J34: =#REF! -> #REF! | K34: =#REF! -> #REF! | L34: =#REF! -> #REF! | M34: =#REF! -> #REF! | N34: =#REF! -> #REF! | O34: =#REF! -> #REF!
A35: 23 | B35: ='[2]23'!$C$1 -> Especialização em Comunicação e Marketing Político | C35: 12 | D35: ='DEZ24'!L36 -> Branding E Selfmarketing | E35: =DEZEMBRO26!K36 -> Partidos Políticos e Sistemas Partidários | F35: =JANEIRO26!K35 -> Planejamento de Mídia | G35: =#REF! -> #REF! | H35: =#REF! -> #REF! | I35: =#REF! -> #REF! | J35: =#REF! -> #REF! | K35: =#REF! -> #REF! | L35: =#REF! -> #REF! | M35: =#REF! -> #REF! | N35: =#REF! -> #REF! | O35: =#REF! -> #REF!
A36: 24 | B36: ='[2]24'!$C$1 -> Especialização em Comunicação Estratégica e Marketing Político | C36: 6 | D36: ='DEZ24'!L37 -> Branding e Selfmarketing | E36: =DEZEMBRO26!K37 -> Marketing Digital | F36: =JANEIRO26!K36 -> Publicidade e Propaganda | G36: =#REF! -> #REF! | H36: =#REF! -> #REF! | I36: =#REF! -> #REF! | J36: =#REF! -> #REF! | K36: =#REF! -> #REF! | L36: =#REF! -> #REF! | M36: =#REF! -> #REF! | N36: =#REF! -> #REF! | O36: =#REF! -> #REF!
D37: ='DEZ24'!L38 -> Marketing | E37: =DEZEMBRO26!K38 -> Comportamento Político | F37: =JANEIRO26!K37 -> Análise do Discurso | G37: =#REF! -> #REF! | H37: =#REF! -> #REF! | I37: =#REF! -> #REF! | J37: =#REF! -> #REF! | K37: =#REF! -> #REF! | L37: =#REF! -> #REF! | M37: =#REF! -> #REF! | N37: =#REF! -> #REF! | O37: =#REF! -> #REF!
A38: 25 | B38: ='[2]25'!$C$1 -> Especialização em Gestão de Contratos Públicos | C38: 12 | D38: ='DEZ24'!L39 -> Contabilidade Pública | E38: =DEZEMBRO26!K39 -> Auditoria | F38: =JANEIRO26!K38 -> Licitação e Contratos | G38: =#REF! -> #REF! | H38: =#REF! -> #REF! | I38: =#REF! -> #REF! | J38: =#REF! -> #REF! | K38: =#REF! -> #REF! | L38: =#REF! -> #REF! | M38: =#REF! -> #REF! | N38: =#REF! -> #REF! | O38: =#REF! -> #REF!
A39: 26 | B39: ='[2]26'!$C$1 -> Especialização em Administração de Contratos Públicos | C39: 6 | D39: ='DEZ24'!L40 -> Contabilidade Pública | E39: =DEZEMBRO26!K40 -> Auditoria | F39: =JANEIRO26!K39 -> Teoria Geral dos Contratos | G39: =#REF! -> #REF! | H39: =#REF! -> #REF! | I39: =#REF! -> #REF! | J39: =#REF! -> #REF! | K39: =#REF! -> #REF! | L39: =#REF! -> #REF! | M39: =#REF! -> #REF! | N39: =#REF! -> #REF! | O39: =#REF! -> #REF!
D40: ='DEZ24'!L41 -> Gestão de Informações no Setor Público | E40: =DEZEMBRO26!K41 -> Noções de Direito | F40: =JANEIRO26!K40 -> Fundamentos da Administração | G40: =#REF! -> #REF! | H40: =#REF! -> #REF! | I40: =#REF! -> #REF! | J40: =#REF! -> #REF! | K40: =#REF! -> #REF! | L40: =#REF! -> #REF! | M40: =#REF! -> #REF! | N40: =#REF! -> #REF! | O40: =#REF! -> #REF!
...

Sheet DEZ24
A1: Área | B1: ORDEM N. | C1: UNG | D1: UNAMA | E1: UNINORTE | F1: UNINABUCO | G1: UNIFACIMED | H1: UNIFAEL | I1: COD. CURSO | J1: Curso | K1: Tempo | L1: Nome da disciplina | M1: Turmas | O1: Coordenador | P1: Tutor Learn | Q1: JANEIRO | XDV1: Curso | XDW1: JANEIRO | XDX1: FEVEREIRO | XDY1: MARÇO | XDZ1: ABRIL | XEA1: MAIO | XEB1: JUNHO | XEC1: JULHO | XED1: AGOSTO | XEE1: SETEMBRO | XEF1: OUTUBRO | XEG1: NOVEMBRO | XEH1: DEZEMBRO
A2: TODAS | J2: TODOS | M2: Inicial | N2: Final | S2: RELATÓRIO | XDV2: Administração de Departamento Pessoal
A3: Direito | B3: 1 | C3: EP002000 | D3: EP002000U | E3: EP00041 | F3: EP00041 | H3: EP00041 | I3: EADP003 | J3: Especialização em Direito do Consumidor | K3: 12 | L3: ='[2]1'!$D$5 -> HOSPITAIS E PLANOS DE SAÚDE FRENTE AO CDC | M3: =EDATE('[3]DEZEMBRO-23'!$L$3,1) -> 44986 | N3: =EDATE('[3]DEZEMBRO-23'!$M$3,1) -> 45292 | O3: patricia.marreirros2 | P3: joelmamds | S3: TUTORES | T3: QTD. DISCIPLINAS | U3: ÁREAS | V3: QTD. CURSO | W3: COORDENADORES | X3: QTD. DISCIPLINAS | XDV3: Didática e Metodologia do Ensino de Geografia
A4: Direito | B4: 2 | C4: EP00040 | D4: EP001900 | E4: EP13400 | F4: EP00040 | H4: EP00040 | I4: EADP200 | J4: Especialização em Direito nas Relações de Consumo | K4: 6 | L4: ='[2]2'!$D$6 -> Publicidade e Propaganda no CDC | M4: =EDATE('[3]DEZEMBRO-23'!$L$4,1) -> 45139 | N4: =EDATE('[3]DEZEMBRO-23'!$M$4,1) -> 45292 | O4: patricia.marreirros2 | P4: joelmamds | S4: alcineidefes | T4: =COUNTIF(P:P,S4) -> 18 | U4: Gestão | V4: =COUNTIF(A:A,U4) -> 76 | W4: caio.lima | X4: =COUNTIF(O:O,W4) -> 46 | XDV4: Didática e Metodologia do Ensino de Língua Portuguesa | XES4: Contabilidade pública | XEV4: Gestão | XEW4: Marcio
C5: EP00034 | D5: EP610600 | E5: EP13000 | F5: EP00034 | H5: EP00034 | I5: EADP200 | J5: Especialização em Direito nas Relações de Consumo | K5: 6 | L5: ='[2]2'!$F$17 -> A Proteção Contratual do Consumidor | M5: =EDATE('[3]DEZEMBRO-23'!$L$5,1) -> 45139 | N5: =EDATE('[3]DEZEMBRO-23'!$M$5,1) -> 45261 | O5: patricia.marreirros2 | P5: joelmamds | S5: carla.cunha | T5: =COUNTIF(P:P,S5) -> 13 | U5: Saúde | V5: =COUNTIF(A:A,U5) -> 46 | W5: marcio.oliveira | X5: =COUNTIF(O:O,W5) -> 207 | XDV5: Direito Público e Administração Pública | XEV5: Saúde | XEW5: Marcio
A6: Direito | B6: 3 | C6: EP003100 | D6: EP003100U | E6: EP12600 | F6: EP00018 | H6: EP00018 | I6: EADP002 | J6: Especialização em Direito Civil e Processo Civil | K6: 12 | L6: ='[2]3'!$D$6 -> Processo Constitucional | M6: =EDATE('[3]DEZEMBRO-23'!$L$3,1) -> 44986 | N6: =EDATE('[3]DEZEMBRO-23'!$M$3,1) -> 45292 | O6: patricia.marreirros2 | P6: joelmamds | S6: daniel.vasconcelos2 | T6: =COUNTIF(P:P,S6) -> 13 | U6: Educação | V6: =COUNTIF(A:A,U6) -> 50 | W6: patricia.marreirros2 | X6: =COUNTIF(O:O,W6) -> 12 | XDV6: Engenharia de Operações e Logística | XEV6: Educação | XEW6: Patricia
A7: Direito | B7: 4 | C7: EP00015 | D7: EP002500U | E7: EP12000 | F7: EP00015 | H7: EP00015 | I7: EADP055 | J7: Especialização em Direito Civil | K7: 6 | L7: ='[2]4'!$D$6 -> Direito da Sucessões | M7: =EDATE('[3]DEZEMBRO-23'!$L$4,1) -> 45139 | N7: =EDATE('[3]DEZEMBRO-23'!$M$4,1) -> 45292 | O7: patricia.marreirros2 | P7: joelmamds | S7: danielle.viana | T7: =COUNTIF(P:P,S7) -> 28 | U7: Direito | V7: =COUNTIF(A:A,U7) -> 16 | XDV7: Engenharia de Operações e Logística | XEV7: direito | XEW7: Patricia
C8: EP002300 | D8: EP002300U | E8: EP11800 | F8: EP002300A | H8: EP002300A | I8: EADP055 | J8: Especialização em Direito Civil | K8: 6 | L8: ='[2]4'!$D$11 -> Direito Civil: Parte Geral e Obrigações | M8: =EDATE('[3]DEZEMBRO-23'!$L$5,1) -> 45139 | N8: =EDATE('[3]DEZEMBRO-23'!$M$5,1) -> 45261 | O8: patricia.marreirros2 | P8: joelmamds | S8: diogo.costa | T8: =COUNTIF(P:P,S8) -> 24 | U8: Tecnologia | V8: =COUNTIF(A:A,U8) -> 42 | XDV8: Engenharia de Produção e Operações | XEV8: Tecnologia | XEW8: Caio
A9: Direito | B9: 5 | C9: EP005300 | D9: EP005300U | E9: EP14000 | F9: EP00052 | H9: EP00052 | I9: EADP004 | J9: Especialização em Direito Material e Processual do Trabalho | K9: 12 | L9: ='[2]5'!$D$6 -> Ministério Público do Trabalho | M9: =EDATE('[3]DEZEMBRO-23'!$L$3,1) -> 44986 | N9: =EDATE('[3]DEZEMBRO-23'!$M$3,1) -> 45292 | O9: patricia.marreirros2 | P9: palomanf | T9: =COUNTIF(P:P,S9) -> 0 | U9: Design | V9: =COUNTIF(A:A,U9) -> 8 | XDV9: Engenharia de Produção e Operações | XEV9: design | XEW9: Caio
A10: Direito | B10: 6 | C10: EP672801 | D10: EP182100 | E10: EP14700 | F10: EP672800 | H10: EP00046 | I10: EADP205 | J10: Especialização em Direito do Trabalho | K10: 6 | L10: ='[2]6'!$D$6 -> Direito Individual do Trabalho - Contrato de Trabalho | M10: =EDATE('[3]DEZEMBRO-23'!$L$4,1) -> 45139 | N10: =EDATE('[3]DEZEMBRO-23'!$M$4,1) -> 45292 | O10: patricia.marreirros2 | P10: palomanf | S10: eva.lozano | T10: =COUNTIF(P:P,S10) -> 22 | XDV10: Engenharia, Meio Ambiente e Saneamento Básico
C11: EP00051 | D11: EP005200U | E11: EP14100 | F11: EP00051 | H11: EP00051 | I11: EADP205 | J11: Especialização em Direito do Trabalho | K11: 6 | L11: ='[2]6'!$D$11 -> A Interpretação da Jurisprudência do TST em Matéria de Direito e Processo do Trabalho | M11: =EDATE('[3]DEZEMBRO-23'!$L$5,1) -> 45139 | N11: =EDATE('[3]DEZEMBRO-23'!$M$5,1) -> 45261 | O11: patricia.marreirros2 | P11: palomanf | S11: palomanf | T11: =COUNTIF(P:P,S11) -> 13 | XDV11: ESPECIALIZAÇÃO EM ADMINISTRAÇÃO PÚBLICA E DIREITO PÚBLICO
A12: Direito | B12: 7 | C12: EP001000 | D12: EP001000U | E12: EP11400 | F12: EP00010 | H12: EP00010 | I12: EADP001 | J12: Especialização em Direito Ambiental | K12: 12 | L12: ='[2]7'!$D$6 -> Tutela Civil do Meio Ambiente | M12: =EDATE('[3]DEZEMBRO-23'!$L$3,1) -> 44986 | N12: =EDATE('[3]DEZEMBRO-23'!$M$3,1) -> 45292 | O12: patricia.marreirros2 | P12: palomanf | S12: joelmamds | T12: =COUNTIF(P:P,S12) -> 8 | XDV12: ESPECIALIZAÇÃO EM ADMINISTRAÇÃO PÚBLICA E DIREITO PÚBLICO
A13: Direito | B13: 8 | C13: EP674001 | D13: EP674000 | E13: EP11500 | F13: EP674000 | H13: EP674000 | I13: EADP197 | J13: Especialização em Direito e Meio Ambiente | K13: 6 | L13: ='[2]8'!$D$6 -> Tutela e responsabilidade Administrativa do Meio Ambiente | M13: =EDATE('[3]DEZEMBRO-23'!$L$4,1) -> 45139 | N13: =EDATE('[3]DEZEMBRO-23'!$M$4,1) -> 45292 | O13: patricia.marreirros2 | P13: palomanf | S13: marcela.mascena2 | T13: =COUNTIF(P:P,S13) -> 26 | XDV13: ESPECIALIZAÇÃO EM CONTABILIDADE GERENCIAL
C14: EP00005 | D14: EP000500U | E14: EP11700 | F14: EP00005 | H14: EP00005 | I14: EADP197 | J14: Especialização em Direito e Meio Ambiente | K14: 6 | L14: ='[2]8'!$D$11 -> Licenciamento Ambiental | M14: =EDATE('[3]DEZEMBRO-23'!$L$5,1) -> 45139 | N14: =EDATE('[3]DEZEMBRO-23'!$M$5,1) -> 45261 | O14: patricia.marreirros2 | P14: palomanf | S14: pamela.souza | T14: =COUNTIF(P:P,S14) -> 15 | XDV14: ESPECIALIZAÇÃO EM CONTABILIDADE GERENCIAL
A15: Gestão | B15: 9 | C15: EP00148 | D15: EP011400U | E15: EP00148 | F15: EP00148 | H15: EP00148 | I15: EADP014 | J15: MBA em Gestão da Qualidade e Gestão Ambiental | K15: 12 | L15: ='[2]9'!$D$6 -> NBR - ISO 14001 e Auditorias Ambientais | M15: =EDATE('[3]DEZEMBRO-23'!$L$3,1) -> 44986 | N15: =EDATE('[3]DEZEMBRO-23'!$M$3,1) -> 45292 | O15: marcio.oliveira | P15: pedro.pontes | S15: paulamds | T15: =COUNTIF(P:P,S15) -> 16 | XDV15: ESPECIALIZAÇÃO EM ENGENHARIA AMBIENTAL E SANEAMENTO BÁSICO
A16: Gestão | B16: 10 | C16: EP00149 | D16: EP188300 | E16: EP00149 | F16: EP00149 | H16: EP00149 | I16: EADP204 | J16: MBA em Meio Ambiente e Gestão da Qualidade | K16: 6 | L16: ='[2]10'!$D$6 -> Metodologia 6 Sigmas | M16: =EDATE('[3]DEZEMBRO-23'!$L$4,1) -> 45139 | N16: =EDATE('[3]DEZEMBRO-23'!$M$4,1) -> 45292 | O16: marcio.oliveira | P16: rodrigoodm | S16: pedro.pontes | T16: =COUNTIF(P:P,S16) -> 12 | XDV16: ESPECIALIZAÇÃO EM ENGENHARIA AMBIENTAL E SANEAMENTO BÁSICO
C17: EP00151 | D17: EP011200U | E17: EP00151 | F17: EP00151 | H17: EP00151 | I17: EADP204 | J17: MBA em Meio Ambiente e Gestão da Qualidade | K17: 6 | L17: ='[2]10'!$D$11 -> Padronização e Controle de Documentos e Registros | M17: =EDATE('[3]DEZEMBRO-23'!$L$5,1) -> 45139 | N17: =EDATE('[3]DEZEMBRO-23'!$M$5,1) -> 45261 | O17: marcio.oliveira | P17: rodrigoodm | S17: pollyana.lima | T17: =COUNTIF(P:P,S17) -> 23 | XDV17: ESPECIALIZAÇÃO EM GESTÃO DE DEPARTAMENTO PESSOAL
A18: Gestão | B18: 11 | C18: EP013600 | D18: EP013600U | E18: EP00176 | F18: EP00176 | H18: EP00176 | I18: EADP017 | J18: MBA em Gestão Empresarial | K18: 12 | L18: ='[2]11'!$D$6 -> GESTÃO DE COMPRAS E LOGÍSTICA | M18: =EDATE('[3]DEZEMBRO-23'!$L$3,1) -> 44986 | N18: =EDATE('[3]DEZEMBRO-23'!$M$3,1) -> 45292 | O18: marcio.oliveira | P18: rodrigoodm | S18: rodrigoodm | T18: =COUNTIF(P:P,S18) -> 21 | XDV18: ESPECIALIZAÇÃO EM GESTÃO DE DEPARTAMENTO PESSOAL
A19: Gestão | B19: 12 | C19: EP008500 | D19: EP00103 | E19: EP00103 | F19: EP00103 | H19: EP00103 | I19: EADP316 | J19: MBA em Gestão de Empresas | K19: 6 | L19: ='[2]12'!$D$6 -> PLANEJAMENTO ESTRATÉGICO | M19: =EDATE('[3]DEZEMBRO-23'!$L$4,1) -> 45139 | N19: =EDATE('[3]DEZEMBRO-23'!$M$4,1) -> 45292 | O19: marcio.oliveira | P19: pedro.pontes | S19: selma.lins | T19: =COUNTIF(P:P,S19) -> 15 | XDV19: ESPECIALIZAÇÃO EM PROCESSOS GERENCIAIS
C20: EP011600 | D20: EP00153 | E20: EP00153 | F20: EP00153 | H20: EP00153 | I20: EADP316 | J20: MBA em Gestão de Empresas | K20: 6 | L20: ='[2]12'!$D$11 -> ASSESMENT, COACHING E MENTORING | M20: =EDATE('[3]DEZEMBRO-23'!$L$5,1) -> 45139 | N20: =EDATE('[3]DEZEMBRO-23'!$M$5,1) -> 45261 | O20: marcio.oliveira | P20: pedro.pontes | S20: tarcila.maciel | T20: =COUNTIF(P:P,S20) -> 17 | XDV20: ESPECIALIZAÇÃO EM PROCESSOS GERENCIAIS
A21: Gestão | B21: 13 | C21: EP014600 | D21: EP014600U | E21: EP00188 | F21: EP00188 | H21: EP00188 | I21: EADP019 | J21: MBA em Gestão Pública | K21: 12 | L21: ='[2]13'!$D$6 -> Gestão Ambiental, Ética e Cidadania na Gestão Pública | M21: =EDATE('[3]DEZEMBRO-23'!$L$3,1) -> 44986 | N21: =EDATE('[3]DEZEMBRO-23'!$M$3,1) -> 45292 | O21: marcio.oliveira | P21: rodrigoodm | S21: williamasdas2 | T21: =COUNTIF(P:P,S21) -> 0 | XDV21: ESPECIALIZAÇÃO EM PSICOPEDAGOGIA NA EDUCAÇÃO ESPECIAL
A22: Gestão | B22: 14 | C22: EP001950 | D22: EP00195 | E22: EP00195 | F22: EP00195 | H22: EP00195 | I22: EADP180 | J22: MBA em Administração Pública | K22: 6 | L22: ='[2]14'!$D$6 -> Gestão Estratégica da Tecnologia da Informação | M22: =EDATE('[3]DEZEMBRO-23'!$L$4,1) -> 45139 | N22: =EDATE('[3]DEZEMBRO-23'!$M$4,1) -> 45292 | O22: marcio.oliveira | P22: danielle.viana | S22: paulo.correia | T22: =COUNTIF(P:P,S22) -> 26 | XDV22: ESPECIALIZAÇÃO EM PSICOPEDAGOGIA NA EDUCAÇÃO ESPECIAL
C23: EP001910 | D23: EP00191 | E23: EP00191 | F23: EP00191 | H23: EP00191 | I23: EADP180 | J23: MBA em Administração Pública | K23: 6 | L23: ='[2]14'!$D$11 -> Direito Constitucional e Administrativo | M23: =EDATE('[3]DEZEMBRO-23'!$L$5,1) -> 45139 | N23: =EDATE('[3]DEZEMBRO-23'!$M$5,1) -> 45261 | O23: marcio.oliveira | P23: joelmamds | S23: vanessadol | T23: =COUNTIF(P:P,S23) -> 8 | XDV23: ESPECIALIZAÇÃO EM ADMINISTRAÇÃO DE PROTEÇÃO DE DADOS
A24: Gestão | B24: 15 | C24: EP013100 | D24: EP013100U | E24: EP00168 | F24: EP00168 | H24: EP00168 | I24: EADP016 | J24: MBA em Gestão de Projetos | K24: 12 | L24: ='[2]15'!$D$6 -> GESTÃO DE CONTRATAÇÃO DE PROJETOS | M24: =EDATE('[3]DEZEMBRO-23'!$L$3,1) -> 44986 | N24: =EDATE('[3]DEZEMBRO-23'!$M$3,1) -> 45292 | O24: marcio.oliveira | P24: pedro.pontes | XDV24: ESPECIALIZAÇÃO EM ADMINISTRAÇÃO DE PROTEÇÃO DE DADOS
A25: Gestão | B25: 16 | C25: EP013100 | D25: EP00168 | E25: EP00168 | F25: EP00168 | H25: EP00168 | I25: EADP175 | J25: MBA em Gerenciamento de Projetos | K25: 6 | L25: ='[2]16'!$D$6 -> GESTÃO DE CONTRATAÇÃO DE PROJETOS | M25: =EDATE('[3]DEZEMBRO-23'!$L$4,1) -> 45139 | N25: =EDATE('[3]DEZEMBRO-23'!$M$4,1) -> 45292 | O25: marcio.oliveira | P25: pedro.pontes | XDV25: ESPECIALIZAÇÃO EM ANTROPOLOGIA E FUNDAMENTOS DA EDUCAÇÃO SOCIAL
C26: EP011600 | D26: EP00153 | E26: EP00153 | F26: EP00153 | H26: EP00153 | I26: EADP175 | J26: MBA em Gerenciamento de Projetos | K26: 6 | L26: ='[2]16'!$D$11 -> ASSESMENT, COACHING E MENTORING | M26: =EDATE('[3]DEZEMBRO-23'!$L$5,1) -> 45139 | N26: =EDATE('[3]DEZEMBRO-23'!$M$5,1) -> 45261 | O26: marcio.oliveira | P26: pedro.pontes | XDV26: Especialização em Arquitetura de Cloud Computing
A27: Gestão | B27: 17 | C27: EP013600 | D27: EP013600U | E27: EP00176 | F27: EP674700 | H27: EP674700 | I27: EADP163 | J27: MBA em Logística Empresarial | K27: 12 | L27: ='[2]17'!$D$6 -> Gestão de Compras e Logística | M27: =EDATE('[3]DEZEMBRO-23'!$L$3,1) -> 44986 | N27: =EDATE('[3]DEZEMBRO-23'!$M$3,1) -> 45292 | O27: marcio.oliveira | P27: rodrigoodm | XDV27: Especialização em Cibersegurança: Monitoramento e Proteção Digital de Negócios
A28: Gestão | B28: 18 | C28: EP673900 | D28: EP673900 | E28: EP673900 | F28: EP673900 | H28: EP673900 | I28: EADP183 | J28: MBA em Logística nas Organizações | K28: 6 | L28: ='[2]18'!$D$6 -> Liderança e Desenvolvimento de Equipes | M28: =EDATE('[3]DEZEMBRO-23'!$L$4,1) -> 45139 | N28: =EDATE('[3]DEZEMBRO-23'!$M$4,1) -> 45292 | O28: marcio.oliveira | P28: rodrigoodm | XDV28: ESPECIALIZAÇÃO EM CUIDADO FARMACÊUTICO ONCOLÓGICO
C29: EP650100 | D29: EP674300 | E29: EP674300 | F29: EP674300 | H29: EP674300 | I29: EADP183 | J29: MBA em Logística nas Organizações | K29: 6 | L29: ='[2]18'!$D$11 -> Gestão da Tecnologia e Informação em Logística - GTI | M29: =EDATE('[3]DEZEMBRO-23'!$L$5,1) -> 45139 | N29: =EDATE('[3]DEZEMBRO-23'!$M$5,1) -> 45261 | O29: marcio.oliveira | P29: rodrigoodm | XDV29: ESPECIALIZAÇÃO EM CUIDADO FARMACÊUTICO ONCOLÓGICO
A30: Gestão | B30: 19 | C30: EP012000 | D30: EP012000 | E30: EP00157 | F30: EP00157 | H30: EP00157 | I30: EADP153 | J30: MBA em Gestão de Pessoas e Relações Trabalhistas | K30: 12 | L30: ='[2]19'!$D$6 -> Gestão da Captação e Retenção de Talentos | M30: =EDATE('[3]DEZEMBRO-23'!$L$3,1) -> 44986 | N30: =EDATE('[3]DEZEMBRO-23'!$M$3,1) -> 45292 | O30: marcio.oliveira | P30: eva.lozano | XDV30: ESPECIALIZAÇÃO EM DESIGN DE INTERIORES COM ÊNFASE EM PROJETOS COMERCIAIS
A31: Gestão | B31: 20 | C31: EP00158 | D31: EP00158 | E31: EP00158 | F31: EP00158 | H31: EP00158 | I31: EADP174 | J31: MBA em Gestão de Relações Trabalhistas | K31: 6 | L31: ='[2]20'!$D$6 -> Seleção, Treinamento e Dinâmica de Grupo | M31: =EDATE('[3]DEZEMBRO-23'!$L$4,1) -> 45139 | N31: =EDATE('[3]DEZEMBRO-23'!$M$4,1) -> 45292 | O31: marcio.oliveira | P31: rodrigoodm | XDV31: ESPECIALIZAÇÃO EM DESIGN DE PROJETOS COMERCIAIS
C32: EP00153 | D32: EP00153 | E32: EP00153 | F32: EP00153 | H32: EP00153 | I32: EADP174 | J32: MBA em Gestão de Relações Trabalhistas | K32: 6 | L32: ='[2]20'!$D$11 -> Assesment, Coaching e Mentoring | M32: =EDATE('[3]DEZEMBRO-23'!$L$5,1) -> 45139 | N32: =EDATE('[3]DEZEMBRO-23'!$M$5,1) -> 45261 | O32: marcio.oliveira | P32: pedro.pontes | XDV32: ESPECIALIZAÇÃO EM DESIGN DE PROJETOS COMERCIAIS
A33: Gestão | B33: 21 | C33: EP681100 | D33: EP183700 | E33: EP674025 | F33: EP674025 | H33: EP674025 | I33: EADP161 | J33: MBA em Gestão Hospitalar | K33: 12 | L33: ='[2]21'!$D$6 -> Gestão e Marketing Hopitalar | M33: =EDATE('[3]DEZEMBRO-23'!$L$3,1) -> 44986 | N33: =EDATE('[3]DEZEMBRO-23'!$M$3,1) -> 45292 | O33: marcio.oliveira | P33: eva.lozano | XDV33: ESPECIALIZAÇÃO EM DEVOPS
A34: Gestão | B34: 22 | C34: EP681100 | D34: EP674025 | E34: EP674025 | F34: EP674025 | H34: EP674025 | I34: EADP179 | J34: MBA em Gestão em Unidades Hospitalares | K34: 6 | L34: ='[2]22'!$D$6 -> Gestão e Marketing Hospitalar | M34: =EDATE('[3]DEZEMBRO-23'!$L$4,1) -> 45139 | N34: =EDATE('[3]DEZEMBRO-23'!$M$4,1) -> 45292 | O34: marcio.oliveira | P34: eva.lozano | XDV34: ESPECIALIZAÇÃO EM DEVOPS
C35: EP681000 | D35: EP674024 | E35: EP674024 | F35: EP674024 | H35: EP674024 | I35: EADP179 | J35: MBA em Gestão em Unidades Hospitalares | K35: 6 | L35: ='[2]22'!$D$11 -> Sistema de Informação para Saúde | M35: =EDATE('[3]DEZEMBRO-23'!$L$5,1) -> 45139 | N35: =EDATE('[3]DEZEMBRO-23'!$M$5,1) -> 45261 | O35: marcio.oliveira | P35: eva.lozano | XDV35: ESPECIALIZAÇÃO EM DIREITO ELEITORAL
A36: Gestão | B36: 23 | C36: EP690200 | D36: EADP11550 | E36: EP817800 | F36: EP689300 | H36: EP689300 | I36: EADP264 | J36: Especialização em Comunicação e Marketing Político | K36: 12 | L36: ='[2]23'!$D$6 -> Branding E Selfmarketing | M36: =EDATE('[3]DEZEMBRO-23'!$L$3,1) -> 44986 | N36: =EDATE('[3]DEZEMBRO-23'!$M$3,1) -> 45292 | O36: marcio.oliveira | P36: eva.lozano | XDV36: ESPECIALIZAÇÃO EM DIREITO PÚBLICO
A37: Gestão | B37: 24 | C37: EP690200 | D37: EADP21400 | E37: EP689300 | F37: EP689300 | H37: EP689300 | I37: EADP280 | J37: Especialização em Comunicação Estratégica e Marketing Político | K37: 6 | L37: ='[2]24'!$D$6 -> Branding e Selfmarketing | M37: =EDATE('[3]DEZEMBRO-23'!$L$4,1) -> 45139 | N37: =EDATE('[3]DEZEMBRO-23'!$M$4,1) -> 45292 | O37: marcio.oliveira | P37: eva.lozano | XDV37: ESPECIALIZAÇÃO EM DIREITO PÚBLICO E ORGANIZAÇÃO PÚBLICA
C38: EP692000 | D38: EADP31200 | E38: EP809900 | F38: EP689300 | H38: EP809900 | I38: EADP280 | J38: Especialização em Comunicação Estratégica e Marketing Político | K38: 6 | L38: ='[2]24'!$D$11 -> Marketing | M38: =EDATE('[3]DEZEMBRO-23'!$L$5,1) -> 45139 | N38: =EDATE('[3]DEZEMBRO-23'!$M$5,1) -> 45261 | O38: marcio.oliveira | P38: eva.lozano | XDV38: ESPECIALIZAÇÃO EM DIREITO PÚBLICO E ORGANIZAÇÃO PÚBLICA
A39: Gestão | B39: 25 | C39: EP613101 | D39: EP613101 | E39: EP817700 | F39: EP613101 | H39: EP613101 | I39: EADP217 | J39: Especialização em Gestão de Contratos Públicos | K39: 12 | L39: ='[2]25'!$D$6 -> Contabilidade Pública | M39: =EDATE('[3]DEZEMBRO-23'!$L$3,1) -> 44986 | N39: =EDATE('[3]DEZEMBRO-23'!$M$3,1) -> 45292 | O39: marcio.oliveira | P39: paulo.correia | XDV39: ESPECIALIZAÇÃO EM ENGENHARIA DE DEVOPS
A40: Gestão | B40: 26 | C40: EP817700 | D40: EP817701 | E40: EP817700 | F40: EP817700 | H40: EP817700 | I40: EADP298 | J40: Especialização em Administração de Contratos Públicos | K40: 6 | L40: ='[2]26'!$D$6 -> Contabilidade Pública | M40: =EDATE('[3]DEZEMBRO-23'!$L$4,1) -> 45139 | N40: =EDATE('[3]DEZEMBRO-23'!$M$4,1) -> 45292 | O40: marcio.oliveira | P40: paulo.correia | XDV40: Especialização em Epidemiologia e Vigilância em Saúde
...

Sheet TUTORES
A1: NOME | B1: ÁREA
A2: ALCINEIDE | B2: SAÚDE
A3: CARLA | B3: DIREITO
A4: CAROLINA | B4: EDUCAÇÃO
A5: DANIEL | B5: EDUCAÇÃO
A6: EVA | B6: GESTÃO
A7: ITALO | B7: GESTÃO
A8: JOELMA | B8: DIREITO
A9: JULIANA | B9: EDUCAÇÃO
A10: LAYS | B10: SAÚDE
A11: MARCELA | B11: GESTÃO
A12: MATHEUS | B12: TECNOLOGIA
... A21: WILLIAM | B21: TECNOLOGIA

Sheet BASE
A1: COD. CURSO | B1: CURSO | C1: TEMPO | D1: DISCIPLINAS
A2: EADP003 | B2: Especialização em Direito do Consumidor | C2: 12 | D2: ='[2]1'!$D$7 -> DEFESA DO CONSUMIDOR EM JUÍZO: DIREITO COLETIVO E DIREITO INDIVIDUAL | XED2: direito | XEE2: Patricia
A3: EADP200 | B3: Especialização em Direito nas Relações de Consumo | C3: 6 | D3: ='[2]2'!$D$8 -> Autuação, Processos e Sanções Administrativos | XED3: Tecnologia | XEE3: Caio
A4: EADP200 | B4: Especialização em Direito nas Relações de Consumo | C4: 6 | D4: ='[2]2'!$F$8 -> Responsabilidade Civil e o Código de Defesa do Consumidor | XED4: design | XEE4: Caio
A5: EADP002 | B5: Especialização em Direito Civil e Processo Civil | C5: 12 | D5: ='[2]3'!$D$8 -> Mediação e Arbitragem
A6: EADP055 | B6: Especialização em Direito Civil | C6: 6 | D6: ='[2]4'!$D$8 -> Aspectos Processuais dos Juizados Especiais, Estaduais e Federais
A7: EADP055 | B7: Especialização em Direito Civil | C7: 6 | D7: ='[2]4'!$F$8 -> Processo Civil: Cautelar e Recursos
A8: EADP004 | B8: Especialização em Direito Material e Processual do Trabalho | C8: 12 | D8: ='[2]5'!$D$8 -> Direito Constitucional do Trabalho
A9: EADP205 | B9: Especialização em Direito do Trabalho | C9: 6 | D9: ='[2]6'!$D$8 -> Meio Ambiente do Trabalho
A10: EADP205 | B10: Especialização em Direito do Trabalho | C10: 6 | D10: ='[2]6'!$F$8 -> Processo do Trabalho - Recursos
A11: EADP001 | B11: Especialização em Direito Ambiental | C11: 12 | D11: ='[2]7'!$D$8 -> Tutela e Responsabilidade Penal
A12: EADP197 | B12: Especialização em Direito e Meio Ambiente | C12: 6 | D12: ='[2]8'!$D$8 -> Estudo de impacto ambiental (EIA) e Relatório de impacto ambiental (RIMA)
A13: EADP197 | B13: Especialização em Direito e Meio Ambiente | C13: 6 | D13: ='[2]8'!$F$8 -> O Direito Constitucional e a questão ambiental
A14: EADP014 | B14: MBA em Gestão da Qualidade e Gestão Ambiental | C14: 12 | D14: ='[2]9'!$D$8 -> Ações Corretivas e Preventivas para Qualidade e Ambientais
A15: EADP204 | B15: MBA em Meio Ambiente e Gestão da Qualidade | C15: 6 | D15: ='[2]10'!$D$8 -> Visão Estratégica e Indicadores de Desempenho
A16: EADP204 | B16: MBA em Meio Ambiente e Gestão da Qualidade | C16: 6 | D16: ='[2]10'!$F$8 -> Gerenciamento de Processos
A17: EADP017 | B17: MBA em Gestão Empresarial | C17: 12 | D17: ='[2]11'!$D$8 -> GESTÃO DE RELACIONAMENTO COM O CLIENTE
A18: EADP316 | B18: MBA em Gestão de Empresas | C18: 6 | D18: ='[2]12'!$D$8 -> NEGOCIAÇÃO PARA LIDERES
A19: EADP316 | B19: MBA em Gestão de Empresas | C19: 6 | D19: ='[2]12'!$F$8 -> GESTÃO CONTÁBIL
A20: EADP019 | B20: MBA em Gestão Pública | C20: 12 | D20: ='[2]13'!$D$8 -> Planejamento Estratégico
A21: EADP180 | B21: MBA em Administração Pública | C21: 6 | D21: ='[2]14'!$D$8 -> Lógica
A22: EADP180 | B22: MBA em Administração Pública | C22: 6 | D22: ='[2]14'!$F$8 -> Estado e Administração Pública
A23: EADP016 | B23: MBA em Gestão de Projetos | C23: 12 | D23: ='[2]15'!$D$8 -> GESTÃO DE ESCOPO DE PROJETOS
A24: EADP175 | B24: MBA em Gerenciamento de Projetos | C24: 6 | D24: ='[2]16'!$D$8 -> GESTÃO DE ESCOPO DE PROJETOS
A25: EADP175 | B25: MBA em Gerenciamento de Projetos | C25: 6 | D25: ='[2]16'!$F$8 -> PRINCÍPIOS DE GERÊNCIA DE PROJETOS
A26: EADP163 | B26: MBA em Logística Empresarial | C26: 12 | D26: ='[2]17'!$D$8 -> Logística de Distribuição
A27: EADP183 | B27: MBA em Logística nas Organizações | C27: 6 | D27: ='[2]18'!$D$8 -> Logística e Distribuição
A28: EADP183 | B28: MBA em Logística nas Organizações | C28: 6 | D28: ='[2]18'!$F$8 -> Gestão de Custos, Riscos e Perdas
A29: EADP153 | B29: MBA em Gestão de Pessoas e Relações Trabalhistas | C29: 12 | D29: ='[2]19'!$D$8 -> Direito Constitucional do Trabalho
A30: EADP174 | B30: MBA em Gestão de Relações Trabalhistas | C30: 6 | D30: ='[2]20'!$D$8 -> Direito Constitucional do Trabalho
A31: EADP174 | B31: MBA em Gestão de Relações Trabalhistas | C31: 6 | D31: ='[2]20'!$F$8 -> Direito Individual do Trabalho - Contrato de Trabalho
A32: EADP161 | B32: MBA em Gestão Hospitalar | C32: 12 | D32: ='[2]21'!$D$8 -> Auditoria Hospitalar
A33: EADP179 | B33: MBA em Gestão em Unidades Hospitalares | C33: 6 | D33: ='[2]22'!$D$8 -> Auditoria Hospitalar
A34: EADP179 | B34: MBA em Gestão em Unidades Hospitalares | C34: 6 | D34: ='[2]22'!$F$8 -> Gestão Estratégica de Pessoas
A35: EADP264 | B35: Especialização em Comunicação e Marketing Político | C35: 12 | D35: ='[2]23'!$D$8 -> Planejamento de Mídia
A36: EADP280 | B36: Especialização em Comunicação Estratégica e Marketing Político | C36: 6 | D36: ='[2]24'!$D$8 -> Publicidade e Propaganda
A37: EADP280 | B37: Especialização em Comunicação Estratégica e Marketing Político | C37: 6 | D37: ='[2]24'!$F$8 -> Análise do Discurso
A38: EADP217 | B38: Especialização em Gestão de Contratos Públicos | C38: 12 | D38: ='[2]25'!$D$8 -> Licitações e Contratos
A39: EADP298 | B39: Especialização em Administração de Contratos Públicos | C39: 6 | D39: ='[2]26'!$D$8 -> Teoria Geral dos Contratos
A40: EADP298 | B40: Especialização em Administração de Contratos Públicos | C40: 6 | D40: ='[2]26'!$F$8 -> Fundamentos da Administração
...

Sheet JANEIRO26
A1: ÁREA | B1: ORDEM N. | C1: UNG | D1: UNAMA | E1: DERBY | F1: UNINASSAU | G1: UNIFAEL | H1: COD. CURSO | I1: CURSO | J1: TEMPO | K1: DISCIPLINA | L1: TURMAS SER CONNECT | N1: COORDENADOR(A) | O1: MEDIADOR RESPONÁVEL
A2: Direito | B2: 1 | C2: EP002200 | D2: EP002200U | E2: EP00043 | F2: EP00043 | G2: EP00043 | H2: EADP003 | I2: Especialização em Direito do Consumidor | J2: 12 | K2: ='[2]1'!$D$7 -> DEFESA DO CONSUMIDOR EM JUÍZO: DIREITO COLETIVO E DIREITO INDIVIDUAL | L2: 45717 | M2: 46023 | N2: CHARLANE KOWALSKI | O2: CARLA
A3: Direito | B3: 2 | C3: EP00039 | D3: EP610500 | E3: EP00039 | F3: EP00039 | G3: EP00039 | H3: EADP200 | I3: Especialização em Direito nas Relações de Consumo | J3: 6 | K3: ='[2]2'!$D$8 -> Autuação, Processos e Sanções Administrativos | L3: 45870 | M3: 46023 | N3: CHARLANE KOWALSKI | O3: JOELMA | XEO3: Gestão | XEP3: Marcio
C4: EP00038 | D4: EP000380 | E4: EP00038 | F4: EP00038 | G4: EP00038 | H4: EADP200 | I4: Especialização em Direito nas Relações de Consumo | J4: 6 | K4: ='[2]2'!$F$8 -> Responsabilidade Civil e o Código de Defesa do Consumidor | L4: 45870 | M4: 45992 | N4: CHARLANE KOWALSKI | O4: CARLA | XEO4: Saúde | XEP4: Marcio
A5: Direito | B5: 3 | C5: EP003200 | D5: EP003200U | E5: EP00021 | F5: EP00021 | G5: EP00021 | H5: EADP002 | I5: Especialização em Direito Civil e Processo Civil | J5: 12 | K5: ='[2]3'!$D$8 -> Mediação e Arbitragem | L5: 45717 | M5: 46023 | N5: CHARLANE KOWALSKI | O5: JOELMA | XEO5: Educação | XEP5: Patricia
A6: Direito | B6: 4 | C6: EP002700 | D6: EP002700U | E6: EP002700A | F6: EP002700A | G6: EP002700A | H6: EADP055 | I6: Especialização em Direito Civil | J6: 6 | K6: ='[2]4'!$D$8 -> Aspectos Processuais dos Juizados Especiais, Estaduais e Federais | L6: 45870 | M6: 46023 | N6: CHARLANE KOWALSKI | O6: CARLA | XEO6: direito | XEP6: Patricia
C7: EP676001 | D7: EP002900 | E7: EP676000 | F7: EP676000 | G7: EP676000 | H7: EADP055 | I7: Especialização em Direito Civil | J7: 6 | K7: ='[2]4'!$F$8 -> Processo Civil: Cautelar e Recursos | L7: 45870 | M7: 45992 | N7: CHARLANE KOWALSKI | O7: CARLA | XEO7: Tecnologia | XEP7: Caio
A8: Direito | B8: 5 | C8: EP004600 | D8: EP004600U | E8: EP00046 | F8: EP00046 | G8: EP00046 | H8: EADP004 | I8: Especialização em Direito Material e Processual do Trabalho | J8: 12 | K8: ='[2]5'!$D$8 -> Direito Constitucional do Trabalho | L8: 45717 | M8: 46023 | N8: CHARLANE KOWALSKI | O8: JOELMA | XEO8: design | XEP8: Caio
A9: Direito | B9: 6 | C9: EP00004 | D9: EP000400U | E9: EP00004 | F9: EP00004 | G9: EP00004 | H9: EADP205 | I9: Especialização em Direito do Trabalho | J9: 6 | K9: ='[2]6'!$D$8 -> Meio Ambiente do Trabalho | L9: 45870 | M9: 46023 | N9: CHARLANE KOWALSKI | O9: CARLA
C10: EP672900 | D10: EP672900 | E10: EP672900 | F10: EP672900 | G10: EP672900 | H10: EADP205 | I10: Especialização em Direito do Trabalho | J10: 6 | K10: ='[2]6'!$F$8 -> Processo do Trabalho - Recursos | L10: 45870 | M10: 45992 | N10: CHARLANE KOWALSKI | O10: CARLA
A11: Direito | B11: 7 | C11: EP001100 | D11: EP001100U | E11: EP00011 | F11: EP00011 | G11: EP00011 | H11: EADP001 | I11: Especialização em Direito Ambiental | J11: 12 | K11: ='[2]7'!$D$8 -> Tutela e Responsabilidade Penal | L11: 45717 | M11: 46023 | N11: CHARLANE KOWALSKI | O11: CARLA
A12: Direito | B12: 8 | C12: EP00007 | D12: EP000700U | E12: EP00007 | F12: EP00007 | G12: EP00007 | H12: EADP197 | I12: Especialização em Direito e Meio Ambiente | J12: 6 | K12: ='[2]8'!$D$8 -> Estudo de impacto ambiental (EIA) e Relatório de impacto ambiental (RIMA) | L12: 45870 | M12: 46023 | N12: CHARLANE KOWALSKI | O12: CARLA
C13: EP00003 | D13: EP000300U | E13: EP00003 | F13: EP00003 | G13: EP00003 | H13: EADP197 | I13: Especialização em Direito e Meio Ambiente | J13: 6 | K13: ='[2]8'!$F$8 -> O Direito Constitucional e a questão ambiental | L13: 45870 | M13: 45992 | N13: CHARLANE KOWALSKI | O13: JOELMA
A14: Gestão | B14: 9 | C14: EP00150 | D14: EP181300 | E14: EP00150 | F14: EP00150 | G14: EP00150 | H14: EADP014 | I14: MBA em Gestão da Qualidade e Gestão Ambiental | J14: 12 | K14: ='[2]9'!$D$8 -> Ações Corretivas e Preventivas para Qualidade e Ambientais | L14: 45717 | M14: 46023 | N14: KATIA GISELY | O14: RODRIGO
A15: Gestão | B15: 10 | C15: EP155100 | D15: EP188200 | E15: EP676001 | F15: EP676001 | G15: EP676001 | H15: EADP204 | I15: MBA em Meio Ambiente e Gestão da Qualidade | J15: 6 | K15: ='[2]10'!$D$8 -> Visão Estratégica e Indicadores de Desempenho | L15: 45870 | M15: 46023 | N15: KATIA GISELY | O15: RODRIGO
C16: EP00146 | D16: EP010700U | E16: EP00146 | F16: EP00146 | G16: EP00146 | H16: EADP204 | I16: MBA em Meio Ambiente e Gestão da Qualidade | J16: 6 | K16: ='[2]10'!$F$8 -> Gerenciamento de Processos | L16: 45870 | M16: 45992 | N16: KATIA GISELY | O16: ITALO
A17: Gestão | B17: 11 | C17: EP013800 | D17: EP013800U | E17: EP00178 | F17: EP00178 | G17: EP00178 | H17: EADP017 | I17: MBA em Gestão Empresarial | J17: 12 | K17: ='[2]11'!$D$8 -> GESTÃO DE RELACIONAMENTO COM O CLIENTE | L17: 45717 | M17: 46023 | N17: KATIA GISELY | O17: ITALO
A18: Gestão | B18: 12 | C18: EP011800 | D18: EP00172 | E18: EP00172 | F18: EP00172 | G18: EP00172 | H18: EADP316 | I18: MBA em Gestão de Empresas | J18: 6 | K18: ='[2]12'!$D$8 -> NEGOCIAÇÃO PARA LIDERES | L18: 45870 | M18: 46023 | N18: KATIA GISELY | O18: MARCELA
C19: EP013400 | D19: EP00174 | E19: EP00174 | F19: EP00174 | G19: EP00174 | H19: EADP316 | I19: MBA em Gestão de Empresas | J19: 6 | K19: ='[2]12'!$F$8 -> GESTÃO CONTÁBIL | L19: 45870 | M19: 45992 | N19: KATIA GISELY | O19: ITALO
A20: Gestão | B20: 13 | C20: EP008500 | D20: EP008500U | E20: EP00103 | F20: EP00103 | G20: EP00103 | H20: EADP019 | I20: MBA em Gestão Pública | J20: 12 | K20: ='[2]13'!$D$8 -> Planejamento Estratégico | L20: 45717 | M20: 46023 | N20: KATIA GISELY | O20: RODRIGO
A21: Gestão | B21: 14 | C21: EP001850 | D21: EP00185 | E21: EP00185 | F21: EP00185 | G21: EP00185 | H21: EADP180 | I21: MBA em Administração Pública | J21: 6 | K21: ='[2]14'!$D$8 -> Lógica | L21: 45870 | M21: 46023 | N21: KATIA GISELY | O21: SELMA
C22: EP001920 | D22: EP00192 | E22: EP00192 | F22: EP00192 | G22: EP00192 | H22: EADP180 | I22: MBA em Administração Pública | J22: 6 | K22: ='[2]14'!$F$8 -> Estado e Administração Pública | L22: 45870 | M22: 45992 | N22: KATIA GISELY | O22: ITALO
A23: Gestão | B23: 15 | C23: EP012700 | D23: EP012700U | E23: EP00164 | F23: EP00164 | G23: EP00164 | H23: EADP016 | I23: MBA em Gestão de Projetos | J23: 12 | K23: ='[2]15'!$D$8 -> GESTÃO DE ESCOPO DE PROJETOS | L23: 45717 | M23: 46023 | N23: KATIA GISELY | O23: MARCELA
A24: Gestão | B24: 16 | C24: EP012700 | D24: EP00164 | E24: EP00164 | F24: EP00164 | G24: EP00164 | H24: EADP175 | I24: MBA em Gerenciamento de Projetos | J24: 6 | K24: ='[2]16'!$D$8 -> GESTÃO DE ESCOPO DE PROJETOS | L24: 45870 | M24: 46023 | N24: KATIA GISELY | O24: MARCELA
C25: EP012600 | D25: EP00163 | E25: EP00163 | F25: EP00163 | G25: EP00163 | H25: EADP175 | I25: MBA em Gerenciamento de Projetos | J25: 6 | K25: ='[2]16'!$F$8 -> PRINCÍPIOS DE GERÊNCIA DE PROJETOS | L25: 45870 | M25: 45992 | N25: KATIA GISELY | O25: RODRIGO
A26: Gestão | B26: 17 | C26: EP682000 | D26: EP179400 | E26: EP674200 | F26: EP674200 | G26: EP674200 | H26: EADP163 | I26: MBA em Logística Empresarial | J26: 12 | K26: Logística e Distribuição | L26: 45717 | M26: 46023 | N26: KATIA GISELY | O26: EVA
A27: Gestão | B27: 18 | C27: EP682000 | D27: EP674200 | E27: EP674200 | F27: EP674200 | G27: EP674200 | H27: EADP183 | I27: MBA em Logística nas Organizações | J27: 6 | K27: ='[2]18'!$D$8 -> Logística e Distribuição | L27: 45870 | M27: 46023 | N27: KATIA GISELY | O27: EVA
C28: EP200300 | D28: EP200300 | E28: EP200300 | F28: EP200300 | G28: EP200300 | H28: EADP183 | I28: MBA em Logística nas Organizações | J28: 6 | K28: ='[2]18'!$F$8 -> Gestão de Custos, Riscos e Perdas | L28: 45870 | M28: 45992 | N28: KATIA GISELY | O28: VALDIR
A29: Gestão | B29: 19 | C29: EP004600 | D29: EP004600 | E29: EP00046 | F29: EP00046 | G29: EP00046 | H29: EADP153 | I29: MBA em Gestão de Pessoas e Relações Trabalhistas | J29: 12 | K29: ='[2]19'!$D$8 -> Direito Constitucional do Trabalho | L29: 45717 | M29: 46023 | N29: KATIA GISELY | O29: JOELMA
A30: Gestão | B30: 20 | C30: EP00046 | D30: EP00046 | E30: EP00046 | F30: EP00046 | G30: EP00046 | H30: EADP174 | I30: MBA em Gestão de Relações Trabalhistas | J30: 6 | K30: ='[2]20'!$D$8 -> Direito Constitucional do Trabalho | L30: 45870 | M30: 46023 | N30: KATIA GISELY | O30: JOELMA
C31: EP674300 | D31: EP672800 | E31: EP672800 | F31: EP672800 | G31: EP672800 | H31: EADP174 | I31: MBA em Gestão de Relações Trabalhistas | J31: 6 | K31: ='[2]20'!$F$8 -> Direito Individual do Trabalho - Contrato de Trabalho | L31: 45870 | M31: 45992 | N31: KATIA GISELY | O31: JOELMA
A32: Gestão | B32: 21 | C32: EP680800 | D32: EP183400 | E32: EP674022 | F32: EP674022 | G32: EP674022 | H32: EADP161 | I32: MBA em Gestão Hospitalar | J32: 12 | K32: ='[2]21'!$D$8 -> Auditoria Hospitalar | L32: 45717 | M32: 46023 | N32: KATIA GISELY | O32: VALDIR
A33: Gestão | B33: 22 | C33: EP680800 | D33: EP674022 | E33: EP674022 | F33: EP674022 | G33: EP674022 | H33: EADP179 | I33: MBA em Gestão em Unidades Hospitalares | J33: 6 | K33: ='[2]22'!$D$8 -> Auditoria Hospitalar | L33: 45870 | M33: 46023 | N33: KATIA GISELY | O33: VALDIR
C34: EP012500 | D34: EP00162 | E34: EP00162 | F34: EP00162 | G34: EP00162 | H34: EADP179 | I34: MBA em Gestão em Unidades Hospitalares | J34: 6 | K34: ='[2]22'!$F$8 -> Gestão Estratégica de Pessoas | L34: 45870 | M34: 45992 | N34: KATIA GISELY | O34: MARCELA
A35: Gestão | B35: 23 | C35: EP008200 | D35: EADP21600 | E35: EP00080 | F35: EP00080 | G35: EP00080 | H35: EADP264 | I35: Especialização em Comunicação e Marketing Político | J35: 12 | K35: ='[2]23'!$D$8 -> Planejamento de Mídia | L35: 45717 | M35: 46023 | N35: KATIA GISELY | O35: EVA
A36: Gestão | B36: 24 | C36: EP691500 | D36: EADP21100 | E36: EP809400 | F36: EP809400 | G36: EP809400 | H36: EADP280 | I36: Especialização em Comunicação Estratégica e Marketing Político | J36: 6 | K36: ='[2]24'!$D$8 -> Publicidade e Propaganda | L36: 45870 | M36: 46023 | N36: KATIA GISELY | O36: EVA
C37: EP687700 | D37: EADP31100 | E37: EP682500 | F37: EP682500 | G37: EP682500 | H37: EADP280 | I37: Especialização em Comunicação Estratégica e Marketing Político | J37: 6 | K37: ='[2]24'!$F$8 -> Análise do Discurso | L37: 45870 | M37: 45992 | N37: KATIA GISELY | O37: CAROLINA
A38: Gestão | B38: 25 | C38: EP679801 | D38: EP679800 | E38: EP679800 | F38: EP679800 | G38: EP679800 | H38: EADP217 | I38: Especialização em Gestão de Contratos Públicos | J38: 12 | K38: Licitação e Contratos | L38: 45717 | M38: 46023 | N38: KATIA GISELY | O38: CARLA
A39: Gestão | B39: 26 | C39: EP680101 | D39: EP680100 | E39: EP680100 | F39: EP680100 | G39: EP680100 | H39: EADP298 | I39: Especialização em Administração de Contratos Públicos | J39: 6 | K39: ='[2]26'!$D$8 -> Teoria Geral dos Contratos | L39: 45870 | M39: 46023 | N39: KATIA GISELY | O39: JOELMA
C40: EP001520 | D40: EP001520 | E40: EP00152 | F40: EP00152 | G40: EP00152 | H40: EADP298 | I40: Especialização em Administração de Contratos Públicos | J40: 6 | K40: ='[2]26'!$F$8 -> Fundamentos da Administração | L40: 45870 | M40: 45992 | N40: KATIA GISELY | O40: MARCELA
...

Sheet FEVEREIRO26
A1: ÁREA | B1: ORDEM N. | C1: UNG | D1: UNAMA | E1: DERBY | F1: UNINASSAU | G1: UNIFAEL | H1: COD. CURSO | I1: CURSO | J1: TEMPO | K1: DISCIPLINA | L1: SER CONNECT | N1: COORDENADOR(A) | O1: MEDIADORES | P1: ENTURMAÇÃO VALIDADA | R1: MEDIADORES
A2: Direito | B2: 1 | C2: EP000200 | D2: EP000200U | E2: EP00002 | F2: EP00002 | G2: EP00002 | H2: EADP003 | I2: Especialização em Direito do Consumidor | J2: 12 | K2: ='[2]1'!$D$8 -> HERMENÊUTICA JURÍDICA | L2: 45748 | M2: 46054 | N2: CHARLANE KOWALSKI | O2: JOELMA | R2: ALCINEIDE
A3: Direito | B3: 2 | C3: EP00002 | D3: EP630200 | E3: EP00002 | F3: EP00002 | G3: EP00002 | H3: EADP200 | I3: Especialização em Direito nas Relações de Consumo | J3: 6 | K3: ='[2]2'!$D$9 -> Hermenêutica Jurídica | L3: 45901 | M3: 46054 | N3: CHARLANE KOWALSKI | O3: JOELMA | R3: CARLA
C4: EP00043 | D4: EP630500 | E4: EP00043 | F4: EP00043 | G4: EP00043 | H4: EADP200 | I4: Especialização em Direito nas Relações de Consumo | J4: 6 | K4: ='[2]2'!$F$9 -> Defesa do Consumidor em Juízo: Direito Coletivo e Direito Individual | L4: 45901 | M4: 46023 | N4: CHARLANE KOWALSKI | O4: CARLA | R4: CAROLINA
A5: Direito | B5: 3 | C5: EP000200 | D5: EP000200U | E5: EP00002 | F5: EP00002 | G5: EP00002 | H5: EADP002 | I5: Especialização em Direito Civil e Processo Civil | J5: 12 | K5: ='[2]3'!$D$9 -> Hermenêutica Jurídica | L5: 45748 | M5: 46054 | N5: CHARLANE KOWALSKI | O5: JOELMA | R5: DANIEL
A6: Direito | B6: 4 | C6: EP00002 | D6: EP000200U | E6: EP00002 | F6: EP00002 | G6: EP00002 | H6: EADP055 | I6: Especialização em Direito Civil | J6: 6 | K6: ='[2]4'!$D$9 -> Hermenêutica Jurídica | L6: 45901 | M6: 46054 | N6: CHARLANE KOWALSKI | O6: JOELMA | R6: EVA
C7: EP00021 | D7: EP003200U | E7: EP00021 | F7: EP00021 | G7: EP00021 | H7: EADP055 | I7: Especialização em Direito Civil | J7: 6 | K7: ='[2]4'!$F$9 -> Mediação e Arbitragem | L7: 45901 | M7: 46023 | N7: CHARLANE KOWALSKI | O7: JOELMA | R7: ITALO
A8: Direito | B8: 5 | C8: EP000200 | D8: EP000200U | E8: EP00002 | F8: EP00002 | G8: EP00002 | H8: EADP004 | I8: Especialização em Direito Material e Processual do Trabalho | J8: 12 | K8: ='[2]5'!$D$9 -> Hermenêutica Jurídica | L8: 45748 | M8: 46054 | N8: CHARLANE KOWALSKI | O8: JOELMA | R8: JOELMA
A9: Direito | B9: 6 | C9: EP00002 | D9: EP000200U | E9: EP00002 | F9: EP00002 | G9: EP00002 | H9: EADP205 | I9: Especialização em Direito do Trabalho | J9: 6 | K9: ='[2]6'!$D$9 -> Hermenêutica Jurídica | L9: 45901 | M9: 46054 | N9: CHARLANE KOWALSKI | O9: JOELMA | R9: JULIANA
C10: EP00046 | D10: EP004600 | E10: EP00046 | F10: EP00046 | G10: EP00046 | H10: EADP205 | I10: Especialização em Direito do Trabalho | J10: 6 | K10: Direito Constitucional do Trabalho | L10: 45901 | M10: 46023 | N10: CHARLANE KOWALSKI | O10: JOELMA | R10: LAYS
A11: Direito | B11: 7 | C11: EP000200 | D11: EP000200U | E11: EP00002 | F11: EP00002 | G11: EP00002 | H11: EADP001 | I11: Especialização em Direito Ambiental | J11: 12 | K11: ='[2]7'!$D$9 -> Hermenêutica Jurídica | L11: 45748 | M11: 46054 | N11: CHARLANE KOWALSKI | O11: JOELMA | R11: MARCELA
A12: Direito | B12: 8 | C12: EP00002 | D12: EP000200U | E12: EP00002 | F12: EP00002 | G12: EP00002 | H12: EADP197 | I12: Especialização em Direito e Meio Ambiente | J12: 6 | K12: ='[2]8'!$D$9 -> Hermenêutica Jurídica | L12: 45901 | M12: 46054 | N12: CHARLANE KOWALSKI | O12: JOELMA | R12: MATHEUS
C13: EP00011 | D13: EP001100U | E13: EP00011 | F13: EP00011 | G13: EP00011 | H13: EADP197 | I13: Especialização em Direito e Meio Ambiente | J13: 6 | K13: ='[2]8'!$F$9 -> Tutela e Responsabilidade Penal | L13: 45901 | M13: 46023 | N13: CHARLANE KOWALSKI | O13: CARLA | R13: PAULA
A14: Gestão | B14: 9 | C14: EP010500 | D14: EP010500U | E14: EP00147 | F14: EP00147 | G14: EP00147 | H14: EADP014 | I14: MBA em Gestão da Qualidade e Gestão Ambiental | J14: 12 | K14: ='[2]9'!$D$9 -> Planejamento Ambiental | L14: 45748 | M14: 46054 | N14: KATIA GISELY | O14: ITALO | R14: PAULO
A15: Gestão | B15: 10 | C15: EP00147 | D15: EP010500U | E15: EP00147 | F15: EP00147 | G15: EP00147 | H15: EADP204 | I15: MBA em Meio Ambiente e Gestão da Qualidade | J15: 6 | K15: ='[2]10'!$D$9 -> Planejamento Ambiental | L15: 45901 | M15: 46054 | N15: KATIA GISELY | O15: ITALO | R15: RODRIGO
C16: EP00150 | D16: EP181300 | E16: EP00150 | F16: EP00150 | G16: EP00150 | H16: EADP204 | I16: MBA em Meio Ambiente e Gestão da Qualidade | J16: 6 | K16: ='[2]10'!$F$9 -> Ações Corretivas e Preventivas para Qualidade e Ambientais | L16: 45901 | M16: 46023 | N16: KATIA GISELY | O16: RODRIGO | R16: SELMA
A17: Gestão | B17: 11 | C17: EP003300 | D17: EP010800U | E17: EP00053 | F17: EP00053 | G17: EP00053 | H17: EADP017 | I17: MBA em Gestão Empresarial | J17: 12 | K17: ='[2]11'!$D$9 -> GESTÃO DE CARREIRA | L17: 45748 | M17: 46054 | N17: KATIA GISELY | O17: RODRIGO | R17: TAFFAREL
A18: Gestão | B18: 12 | C18: EP010800 | D18: EP00053 | E18: EP00053 | F18: EP00053 | G18: EP00053 | H18: EADP178 | I18: MBA em Gestão de Empresas | J18: 6 | K18: ='[2]12'!$D$9 -> GESTÃO DE CARREIRA | L18: 45901 | M18: 46054 | N18: KATIA GISELY | O18: RODRIGO | R18: TARCILA
C19: EP013800 | D19: EP00178 | E19: EP00178 | F19: EP00178 | G19: EP00178 | H19: EADP178 | I19: MBA em Gestão de Empresas | J19: 6 | K19: ='[2]12'!$F$9 -> GESTÃO DE RELACIONAMENTO COM O CLIENTE | L19: 45901 | M19: 46023 | N19: KATIA GISELY | O19: VALDIR | R19: VALDIR
A20: Gestão | B20: 13 | C20: EP013900 | D20: EP010800U | E20: EP00179 | F20: EP00179 | G20: EP00179 | H20: EADP019 | I20: MBA em Gestão Pública | J20: 12 | K20: ='[2]13'!$D$9 -> Gestão de Carreira | L20: 45748 | M20: 46054 | N20: KATIA GISELY | O20: RODRIGO | R20: VANESSA
A21: Gestão | B21: 14 | C21: EP001790 | D21: EP00179 | E21: EP00179 | F21: EP00179 | G21: EP00179 | H21: EADP180 | I21: MBA em Administração Pública | J21: 6 | K21: ='[2]14'!$D$9 -> Gestão de Carreira | L21: 45901 | M21: 46054 | N21: KATIA GISELY | O21: RODRIGO | R21: WILLIAM
C22: EP001030 | D22: EP00103 | E22: EP00103 | F22: EP00103 | G22: EP00103 | H22: EADP180 | I22: MBA em Administração Pública | J22: 6 | K22: ='[2]14'!$F$9 -> Planejamento Estratégico | L22: 45901 | M22: 46023 | N22: KATIA GISELY | O22: ITALO
A23: Gestão | B23: 15 | C23: EP003300 | D23: EP010800U | E23: EP00053 | F23: EP00053 | G23: EP00053 | H23: EADP016 | I23: MBA em Gestão de Projetos | J23: 12 | K23: ='[2]15'!$D$9 -> GESTÃO DE CARREIRA | L23: 45748 | M23: 46054 | N23: KATIA GISELY | O23: RODRIGO
A24: Gestão | B24: 16 | C24: EP000530 | D24: EP00053 | E24: EP00053 | F24: EP00053 | G24: EP00053 | H24: EADP175 | I24: MBA em Gerenciamento de Projetos | J24: 6 | K24: ='[2]16'!$D$9 -> GESTÃO DE CARREIRA | L24: 45901 | M24: 46054 | N24: KATIA GISELY | O24: RODRIGO
C25: EP013200 | D25: EP00169 | E25: EP00169 | F25: EP00169 | G25: EP00169 | H25: EADP175 | I25: MBA em Gerenciamento de Projetos | J25: 6 | K25: ='[2]16'!$F$9 -> GESTÃO DO TEMPO, TOMADA DE DECISÃO E NEGOCIAÇÃO EM PROJETOS | L25: 45901 | M25: 46023 | N25: KATIA GISELY | O25: PAULO
A26: Gestão | B26: 17 | C26: EP682400 | D26: EP179300 | E26: EP674600 | F26: EP674600 | G26: EP674600 | H26: EADP156 | I26: MBA em Logística Empresarial | J26: 12 | K26: ='[2]17'!$D$9 -> Logística Reversa | L26: 45748 | M26: 46054 | N26: KATIA GISELY | O26: MARCELA
A27: Gestão | B27: 18 | C27: EP682400 | D27: EP674600 | E27: EP674600 | F27: EP674600 | G27: EP674600 | H27: EADP183 | I27: MBA em Logística nas Organizações | J27: 6 | K27: ='[2]18'!$D$9 -> Logística Reversa | L27: 45901 | M27: 46054 | N27: KATIA GISELY | O27: MARCELA
C28: EP682300 | D28: EP674500 | E28: EP674500 | F28: EP674500 | G28: EP674500 | H28: EADP183 | I28: MBA em Logística nas Organizações | J28: 6 | K28: ='[2]18'!$F$9 -> Logística Internacional | L28: 45901 | M28: 46023 | N28: KATIA GISELY | O28: EVA
A29: Gestão | B29: 19 | C29: EP005100 | D29: EP005100 | E29: EP00050 | F29: EP00050 | G29: EP00050 | H29: EADP153 | I29: MBA em Gestão de Pessoas e Relações Trabalhistas | J29: 12 | K29: Direito Previdenciário Aplicado Ás Relações de Trabalho | L29: 45748 | M29: 46054 | N29: KATIA GISELY | O29: CARLA
